[PoC RESULT]: False
[PoC MSG]:
============================== Run PoC ==============================
------------------------------ Standard Output ------------------------------
Testing against Django installed in '/workspace/django/django' with up to 64 processes
Found 2 test(s).
System check identified no issues (1 silenced).

------------------------------ Standard Error ------------------------------
Creating test database for alias 'default'...
F
======================================================================
FAIL: test_option_sql_injection (queries.test_explain.ExplainTests)
----------------------------------------------------------------------
Traceback (most recent call last):
  File "/workspace/django/tests/queries/test_explain.py", line 102, in test_option_sql_injection
    qs.explain(**options)
  File "/root/miniconda3/envs/py_38/lib/python3.8/contextlib.py", line 120, in __exit__
    next(self.gen)
  File "/workspace/django/django/test/testcases.py", line 807, in _assert_raises_or_warns_cm
    yield cm
AssertionError: ValueError not raised

======================================================================
FAIL: test_invalid_option_names (queries.test_explain.ExplainTests) [opt"ion]
----------------------------------------------------------------------
Traceback (most recent call last):
  File "/workspace/django/tests/queries/test_explain.py", line 124, in test_invalid_option_names
    qs.explain(**{invalid_option: True})
  File "/root/miniconda3/envs/py_38/lib/python3.8/contextlib.py", line 120, in __exit__
    next(self.gen)
  File "/workspace/django/django/test/testcases.py", line 807, in _assert_raises_or_warns_cm
    yield cm
AssertionError: ValueError not raised

======================================================================
FAIL: test_invalid_option_names (queries.test_explain.ExplainTests) [o'ption]
----------------------------------------------------------------------
Traceback (most recent call last):
  File "/workspace/django/tests/queries/test_explain.py", line 124, in test_invalid_option_names
    qs.explain(**{invalid_option: True})
  File "/root/miniconda3/envs/py_38/lib/python3.8/contextlib.py", line 120, in __exit__
    next(self.gen)
  File "/workspace/django/django/test/testcases.py", line 807, in _assert_raises_or_warns_cm
    yield cm
AssertionError: ValueError not raised

======================================================================
FAIL: test_invalid_option_names (queries.test_explain.ExplainTests) [op`tion]
----------------------------------------------------------------------
Traceback (most recent call last):
  File "/workspace/django/tests/queries/test_explain.py", line 124, in test_invalid_option_names
    qs.explain(**{invalid_option: True})
  File "/root/miniconda3/envs/py_38/lib/python3.8/contextlib.py", line 120, in __exit__
    next(self.gen)
  File "/workspace/django/django/test/testcases.py", line 807, in _assert_raises_or_warns_cm
    yield cm
AssertionError: ValueError not raised

======================================================================
FAIL: test_invalid_option_names (queries.test_explain.ExplainTests) [opti on]
----------------------------------------------------------------------
Traceback (most recent call last):
  File "/workspace/django/tests/queries/test_explain.py", line 124, in test_invalid_option_names
    qs.explain(**{invalid_option: True})
  File "/root/miniconda3/envs/py_38/lib/python3.8/contextlib.py", line 120, in __exit__
    next(self.gen)
  File "/workspace/django/django/test/testcases.py", line 807, in _assert_raises_or_warns_cm
    yield cm
AssertionError: ValueError not raised

======================================================================
FAIL: test_invalid_option_names (queries.test_explain.ExplainTests) [option--]
----------------------------------------------------------------------
Traceback (most recent call last):
  File "/workspace/django/tests/queries/test_explain.py", line 124, in test_invalid_option_names
    qs.explain(**{invalid_option: True})
  File "/root/miniconda3/envs/py_38/lib/python3.8/contextlib.py", line 120, in __exit__
    next(self.gen)
  File "/workspace/django/django/test/testcases.py", line 807, in _assert_raises_or_warns_cm
    yield cm
AssertionError: ValueError not raised

======================================================================
FAIL: test_invalid_option_names (queries.test_explain.ExplainTests) [optio	n]
----------------------------------------------------------------------
Traceback (most recent call last):
  File "/workspace/django/tests/queries/test_explain.py", line 124, in test_invalid_option_names
    qs.explain(**{invalid_option: True})
  File "/root/miniconda3/envs/py_38/lib/python3.8/contextlib.py", line 120, in __exit__
    next(self.gen)
  File "/workspace/django/django/test/testcases.py", line 807, in _assert_raises_or_warns_cm
    yield cm
AssertionError: ValueError not raised

======================================================================
FAIL: test_invalid_option_names (queries.test_explain.ExplainTests) [o
ption]
----------------------------------------------------------------------
Traceback (most recent call last):
  File "/workspace/django/tests/queries/test_explain.py", line 124, in test_invalid_option_names
    qs.explain(**{invalid_option: True})
  File "/root/miniconda3/envs/py_38/lib/python3.8/contextlib.py", line 120, in __exit__
    next(self.gen)
  File "/workspace/django/django/test/testcases.py", line 807, in _assert_raises_or_warns_cm
    yield cm
AssertionError: ValueError not raised

======================================================================
FAIL: test_invalid_option_names (queries.test_explain.ExplainTests) [option;]
----------------------------------------------------------------------
Traceback (most recent call last):
  File "/workspace/django/tests/queries/test_explain.py", line 124, in test_invalid_option_names
    qs.explain(**{invalid_option: True})
  File "/root/miniconda3/envs/py_38/lib/python3.8/contextlib.py", line 120, in __exit__
    next(self.gen)
  File "/workspace/django/django/test/testcases.py", line 807, in _assert_raises_or_warns_cm
    yield cm
AssertionError: ValueError not raised

======================================================================
FAIL: test_invalid_option_names (queries.test_explain.ExplainTests) [你 好]
----------------------------------------------------------------------
Traceback (most recent call last):
  File "/workspace/django/tests/queries/test_explain.py", line 124, in test_invalid_option_names
    qs.explain(**{invalid_option: True})
  File "/root/miniconda3/envs/py_38/lib/python3.8/contextlib.py", line 120, in __exit__
    next(self.gen)
  File "/workspace/django/django/test/testcases.py", line 807, in _assert_raises_or_warns_cm
    yield cm
AssertionError: ValueError not raised

======================================================================
FAIL: test_invalid_option_names (queries.test_explain.ExplainTests) [option[]
----------------------------------------------------------------------
Traceback (most recent call last):
  File "/workspace/django/tests/queries/test_explain.py", line 124, in test_invalid_option_names
    qs.explain(**{invalid_option: True})
  File "/root/miniconda3/envs/py_38/lib/python3.8/contextlib.py", line 120, in __exit__
    next(self.gen)
  File "/workspace/django/django/test/testcases.py", line 807, in _assert_raises_or_warns_cm
    yield cm
AssertionError: ValueError not raised

======================================================================
FAIL: test_invalid_option_names (queries.test_explain.ExplainTests) [option]]
----------------------------------------------------------------------
Traceback (most recent call last):
  File "/workspace/django/tests/queries/test_explain.py", line 124, in test_invalid_option_names
    qs.explain(**{invalid_option: True})
  File "/root/miniconda3/envs/py_38/lib/python3.8/contextlib.py", line 120, in __exit__
    next(self.gen)
  File "/workspace/django/django/test/testcases.py", line 807, in _assert_raises_or_warns_cm
    yield cm
AssertionError: ValueError not raised

----------------------------------------------------------------------
Ran 2 tests in 0.006s

FAILED (failures=12)
Destroying test database for alias 'default'...

------------------------------ Finish Evaluation ------------------------------


[UnitTest RESULT]: None
[UnitTest MSG]:
 None

[Validation TYPE]: validation_fail