[PoC RESULT]: False
[PoC MSG]:
============================== Run PoC ==============================
------------------------------ Standard Output ------------------------------
Testing against Django installed in '/workspace/django/django' with up to 64 processes
Found 5 test(s).
System check identified no issues (0 silenced).

------------------------------ Standard Error ------------------------------
..
======================================================================
FAIL: test_validate_after_get_available_name (file_storage.test_base.StorageValidateFileNameTests) [<object object at 0x7f399c54aa00>] (name='path/to/../test.file')
----------------------------------------------------------------------
Traceback (most recent call last):
  File "/root/miniconda3/envs/py_39/lib/python3.9/unittest/case.py", line 59, in testPartExecutor
    yield
  File "/root/miniconda3/envs/py_39/lib/python3.9/unittest/case.py", line 499, in subTest
    yield
  File "/workspace/django/tests/file_storage/test_base.py", line 55, in test_validate_after_get_available_name
    s.save("valid-file-name.txt", content="irrelevant")
  File "/root/miniconda3/envs/py_39/lib/python3.9/contextlib.py", line 126, in __exit__
    next(self.gen)
  File "/workspace/django/django/test/testcases.py", line 888, in _assert_raises_or_warns_cm
    yield cm
  File "/root/miniconda3/envs/py_39/lib/python3.9/unittest/case.py", line 226, in __exit__
    self._raiseFailure("{} not raised".format(exc_name))
  File "/root/miniconda3/envs/py_39/lib/python3.9/unittest/case.py", line 163, in _raiseFailure
    raise self.test_case.failureException(msg)
AssertionError: SuspiciousFileOperation not raised

======================================================================
FAIL: test_validate_after_get_available_name (file_storage.test_base.StorageValidateFileNameTests) [<object object at 0x7f399c54aa00>] (name='/path/to/test.file')
----------------------------------------------------------------------
Traceback (most recent call last):
  File "/root/miniconda3/envs/py_39/lib/python3.9/unittest/case.py", line 59, in testPartExecutor
    yield
  File "/root/miniconda3/envs/py_39/lib/python3.9/unittest/case.py", line 499, in subTest
    yield
  File "/workspace/django/tests/file_storage/test_base.py", line 55, in test_validate_after_get_available_name
    s.save("valid-file-name.txt", content="irrelevant")
  File "/root/miniconda3/envs/py_39/lib/python3.9/contextlib.py", line 126, in __exit__
    next(self.gen)
  File "/workspace/django/django/test/testcases.py", line 888, in _assert_raises_or_warns_cm
    yield cm
  File "/root/miniconda3/envs/py_39/lib/python3.9/unittest/case.py", line 226, in __exit__
    self._raiseFailure("{} not raised".format(exc_name))
  File "/root/miniconda3/envs/py_39/lib/python3.9/unittest/case.py", line 163, in _raiseFailure
    raise self.test_case.failureException(msg)
AssertionError: SuspiciousFileOperation not raised

======================================================================
FAIL: test_validate_after_internal_save (file_storage.test_base.StorageValidateFileNameTests) [<object object at 0x7f399c54aa00>] (name='/path/to/test.file')
----------------------------------------------------------------------
django.core.exceptions.SuspiciousFileOperation: Detected absolute path attempt in '/path/to/test.file'

During handling of the above exception, another exception occurred:

Traceback (most recent call last):
  File "/root/miniconda3/envs/py_39/lib/python3.9/unittest/case.py", line 59, in testPartExecutor
    yield
  File "/root/miniconda3/envs/py_39/lib/python3.9/unittest/case.py", line 499, in subTest
    yield
  File "/workspace/django/tests/file_storage/test_base.py", line 70, in test_validate_after_internal_save
    s.save("valid-file-name.txt", content="irrelevant")
  File "/root/miniconda3/envs/py_39/lib/python3.9/contextlib.py", line 137, in __exit__
    self.gen.throw(typ, value, traceback)
  File "/workspace/django/django/test/testcases.py", line 889, in _assert_raises_or_warns_cm
    self.assertIn(expected_message, str(getattr(cm, cm_attr)))
  File "/root/miniconda3/envs/py_39/lib/python3.9/unittest/case.py", line 1104, in assertIn
    self.fail(self._formatMessage(msg, standardMsg))
  File "/root/miniconda3/envs/py_39/lib/python3.9/unittest/case.py", line 676, in fail
    raise self.failureException(msg)
AssertionError: "Detected path traversal attempt in '/path/to/test.file'" not found in "Detected absolute path attempt in '/path/to/test.file'"

======================================================================
FAIL: test_validate_before_get_available_name (file_storage.test_base.StorageValidateFileNameTests) [<object object at 0x7f399c54aa00>] (name='path/to/../test.file')
----------------------------------------------------------------------
django.core.exceptions.SuspiciousFileOperation: Detected path traversal attempt in 'path/to/..'

During handling of the above exception, another exception occurred:

Traceback (most recent call last):
  File "/root/miniconda3/envs/py_39/lib/python3.9/unittest/case.py", line 59, in testPartExecutor
    yield
  File "/root/miniconda3/envs/py_39/lib/python3.9/unittest/case.py", line 499, in subTest
    yield
  File "/workspace/django/tests/file_storage/test_base.py", line 38, in test_validate_before_get_available_name
    s.save(name, content="irrelevant")
  File "/root/miniconda3/envs/py_39/lib/python3.9/contextlib.py", line 137, in __exit__
    self.gen.throw(typ, value, traceback)
  File "/workspace/django/django/test/testcases.py", line 889, in _assert_raises_or_warns_cm
    self.assertIn(expected_message, str(getattr(cm, cm_attr)))
  File "/root/miniconda3/envs/py_39/lib/python3.9/unittest/case.py", line 1104, in assertIn
    self.fail(self._formatMessage(msg, standardMsg))
  File "/root/miniconda3/envs/py_39/lib/python3.9/unittest/case.py", line 676, in fail
    raise self.failureException(msg)
AssertionError: "Detected path traversal attempt in 'path/to/../test.file'" not found in "Detected path traversal attempt in 'path/to/..'"

======================================================================
FAIL: test_validate_before_get_available_name (file_storage.test_base.StorageValidateFileNameTests) [<object object at 0x7f399c54aa00>] (name='/path/to/test.file')
----------------------------------------------------------------------
Traceback (most recent call last):
  File "/root/miniconda3/envs/py_39/lib/python3.9/unittest/case.py", line 59, in testPartExecutor
    yield
  File "/root/miniconda3/envs/py_39/lib/python3.9/unittest/case.py", line 499, in subTest
    yield
  File "/workspace/django/tests/file_storage/test_base.py", line 38, in test_validate_before_get_available_name
    s.save(name, content="irrelevant")
  File "/root/miniconda3/envs/py_39/lib/python3.9/contextlib.py", line 126, in __exit__
    next(self.gen)
  File "/workspace/django/django/test/testcases.py", line 888, in _assert_raises_or_warns_cm
    yield cm
  File "/root/miniconda3/envs/py_39/lib/python3.9/unittest/case.py", line 226, in __exit__
    self._raiseFailure("{} not raised".format(exc_name))
  File "/root/miniconda3/envs/py_39/lib/python3.9/unittest/case.py", line 163, in _raiseFailure
    raise self.test_case.failureException(msg)
AssertionError: SuspiciousFileOperation not raised

----------------------------------------------------------------------
Ran 5 tests in 0.114s

FAILED (failures=5)

------------------------------ Finish Evaluation ------------------------------


[UnitTest RESULT]: None
[UnitTest MSG]:
 None

[Validation TYPE]: validation_fail