[PoC RESULT]: False
[PoC MSG]:
============================== Run PoC ==============================
------------------------------ Standard Output ------------------------------
============================= test session starts ==============================
platform linux -- Python 3.8.20, pytest-8.3.5, pluggy-1.5.0 -- /workspace/PoC_env/CVE-2024-0243/bin/python
cachedir: .pytest_cache
rootdir: /workspace/langchain/libs/core
configfile: pyproject.toml
collecting ... collected 10 items / 9 deselected / 1 selected

tests/unit_tests/utils/test_html.py::test_prevent_outside FAILED         [100%]

=================================== FAILURES ===================================
_____________________________ test_prevent_outside _____________________________

    def test_prevent_outside() -> None:
        """Test that prevent outside compares against full base URL."""
        html = (
            '<a href="https://foobar.comic.com">BAD</a>'
            '<a href="https://foobar.comic:9999">BAD</a>'
            '<a href="https://foobar.com:9999">BAD</a>'
            '<a href="http://foobar.com:9999/">BAD</a>'
            '<a href="https://foobar.com/OK">OK</a>'
            '<a href="http://foobar.com/BAD">BAD</a>'  # Change in scheme is not OK here
        )
    
        expected = sorted(
            [
                "https://foobar.com/OK",
            ]
        )
        actual = sorted(
            extract_sub_links(
                html,
                "https://foobar.com/hello/bill.html",
                base_url="https://foobar.com",
                prevent_outside=True,
            )
        )
>       assert actual == expected
E       AssertionError: assert ['http://foob...oobar.com/OK'] == ['https://foobar.com/OK']
E         
E         At index 0 diff: 'http://foobar.com/BAD' != 'https://foobar.com/OK'
E         Left contains one more item: 'https://foobar.com/OK'
E         
E         Full diff:
E           [
E         +     'http://foobar.com/BAD',
E               'https://foobar.com/OK',
E           ]

tests/unit_tests/utils/test_html.py:185: AssertionError
=============================== warnings summary ===============================
../../../PoC_env/CVE-2024-0243/lib/python3.8/site-packages/_pytest/config/__init__.py:1441
  /workspace/PoC_env/CVE-2024-0243/lib/python3.8/site-packages/_pytest/config/__init__.py:1441: PytestConfigWarning: Unknown config option: asyncio_mode
  
    self._warn_or_fail_if_strict(f"Unknown config option: {key}\n")

-- Docs: https://docs.pytest.org/en/stable/how-to/capture-warnings.html
=========================== short test summary info ============================
FAILED tests/unit_tests/utils/test_html.py::test_prevent_outside - AssertionE...
================== 1 failed, 9 deselected, 1 warning in 0.14s ==================

------------------------------ Finish Evaluation ------------------------------


[UnitTest RESULT]: None
[UnitTest MSG]:
 None

[Validation TYPE]: validation_fail