[PoC RESULT]: False
[PoC MSG]:
============================== Run PoC ==============================
------------------------------ Standard Output ------------------------------
Testing against Django installed in '/workspace/django/django' with up to 64 processes
Creating test database for alias 'default'...
Creating test database for alias 'other'...
Destroying test database for alias 'default'...
Destroying test database for alias 'other'...

------------------------------ Standard Error ------------------------------
F
======================================================================
FAIL: test_is_safe_url (utils_tests.test_http.TestUtilsHttp)
----------------------------------------------------------------------
Traceback (most recent call last):
  File "/workspace/django/tests/utils_tests/test_http.py", line 104, in test_is_safe_url
    self.assertFalse(http.is_safe_url(bad_url, host='testserver'), "%s should be blocked" % bad_url)
AssertionError: True is not false : ftp:9999999999 should be blocked

----------------------------------------------------------------------
Ran 1 test in 0.001s

FAILED (failures=1)

------------------------------ Finish Evaluation ------------------------------


[UnitTest RESULT]: None
[UnitTest MSG]:
 None

[Validation TYPE]: validation_fail