[PoC RESULT]: False
[PoC MSG]:
============================== Run PoC ==============================
------------------------------ Standard Output ------------------------------
Testing against Django installed in '/workspace/django/django' with up to 64 processes
System check identified no issues (1 silenced).

------------------------------ Standard Error ------------------------------
F
======================================================================
FAIL: test_order_by_escape_prevention (queries.tests.QuerySetExceptionTests)
----------------------------------------------------------------------
django.core.exceptions.FieldError: Raw column aliases are not permitted in order_by(). Use RawSQL('queries.name);') instead.

During handling of the above exception, another exception occurred:

Traceback (most recent call last):
  File "/workspace/django/tests/queries/tests.py", line 3143, in test_order_by_escape_prevention
    Article.objects.order_by('queries.name);')
  File "/root/miniconda3/envs/py_37/lib/python3.7/contextlib.py", line 130, in __exit__
    self.gen.throw(type, value, traceback)
  File "/workspace/django/django/test/testcases.py", line 692, in _assert_raises_or_warns_cm
    self.assertIn(expected_message, str(getattr(cm, cm_attr)))
AssertionError: "Cannot resolve keyword 'queries.name);' into field. Choices are: created, id, name" not found in "Raw column aliases are not permitted in order_by(). Use RawSQL('queries.name);') instead."

----------------------------------------------------------------------
Ran 1 test in 0.001s

FAILED (failures=1)

------------------------------ Finish Evaluation ------------------------------


[UnitTest RESULT]: None
[UnitTest MSG]:
 None

[Validation TYPE]: validation_fail