[PoC RESULT]: False
[PoC MSG]:
============================== Run PoC ==============================
------------------------------ Standard Output ------------------------------
Testing against Django installed in '/workspace/django/django' with up to 64 processes

------------------------------ Standard Error ------------------------------
Creating test database for alias 'default'...
Traceback (most recent call last):
  File "./runtests.py", line 587, in <module>
    failures = django_tests(
  File "./runtests.py", line 326, in django_tests
    failures = test_runner.run_tests(test_labels or get_installed())
  File "/workspace/django/django/test/runner.py", line 725, in run_tests
    old_config = self.setup_databases(aliases=databases)
  File "/workspace/django/django/test/runner.py", line 643, in setup_databases
    return _setup_databases(
  File "/workspace/django/django/test/utils.py", line 179, in setup_databases
    connection.creation.create_test_db(
  File "/workspace/django/django/db/backends/base/creation.py", line 74, in create_test_db
    call_command(
  File "/workspace/django/django/core/management/__init__.py", line 181, in call_command
    return command.execute(*args, **defaults)
  File "/workspace/django/django/core/management/base.py", line 398, in execute
    output = self.handle(*args, **options)
  File "/workspace/django/django/core/management/base.py", line 89, in wrapped
    res = handle_func(*args, **kwargs)
  File "/workspace/django/django/core/management/commands/migrate.py", line 268, in handle
    emit_post_migrate_signal(
  File "/workspace/django/django/core/management/sql.py", line 42, in emit_post_migrate_signal
    models.signals.post_migrate.send(
  File "/workspace/django/django/dispatch/dispatcher.py", line 180, in send
    return [
  File "/workspace/django/django/dispatch/dispatcher.py", line 181, in <listcomp>
    (receiver, receiver(signal=self, sender=sender, **named))
  File "/workspace/django/django/contrib/sites/management.py", line 20, in create_default_site
    if not Site.objects.using(using).exists():
  File "/workspace/django/django/db/models/query.py", line 808, in exists
    return self.query.has_results(using=self.db)
  File "/workspace/django/django/db/models/sql/query.py", line 550, in has_results
    q = self.exists(using)
  File "/workspace/django/django/db/models/sql/query.py", line 545, in exists
    q.add_extra({'a': 1}, None, None, None, None, None)
  File "/workspace/django/django/db/models/sql/query.py", line 2096, in add_extra
    db_alias = self.model._meta.db
AttributeError: 'Options' object has no attribute 'db'

------------------------------ Finish Evaluation ------------------------------


[UnitTest RESULT]: None
[UnitTest MSG]:
 None

[Validation TYPE]: validation_fail