[PoC RESULT]: False
[PoC MSG]:
============================== Run PoC ==============================
------------------------------ Standard Output ------------------------------
============================= test session starts ==============================
platform linux -- Python 3.8.20, pytest-8.3.5, pluggy-1.5.0 -- /workspace/PoC_env/CVE-2022-24065/bin/python
cachedir: .pytest_cache
rootdir: /workspace/cookiecutter
configfile: setup.cfg
plugins: cov-5.0.0, mock-3.14.0
collecting ... collected 5 items

tests/vcs/test_clone.py::test_clone_should_invoke_vcs_command[git-https://github.com/hello/world.git-world] PASSED [ 20%]
tests/vcs/test_clone.py::test_clone_should_invoke_vcs_command[hg-https://bitbucket.org/foo/bar-bar] FAILED [ 40%]
tests/vcs/test_clone.py::test_clone_should_invoke_vcs_command[git-git@host:gitoliterepo-gitoliterepo] PASSED [ 60%]
tests/vcs/test_clone.py::test_clone_should_invoke_vcs_command[git-git@gitlab.com:cookiecutter/cookiecutter.git-cookiecutter] PASSED [ 80%]
tests/vcs/test_clone.py::test_clone_should_invoke_vcs_command[git-git@github.com:cookiecutter/cookiecutter.git-cookiecutter] PASSED [100%]

=================================== FAILURES ===================================
__ test_clone_should_invoke_vcs_command[hg-https://bitbucket.org/foo/bar-bar] __

self = <MagicMock name='check_output' spec='function' id='139789310646592'>
args = (['hg', 'checkout', '--', 'foobar'],)
kwargs = {'cwd': '/tmp/pytest-of-root/pytest-2/test_clone_should_invoke_vcs_c1/clone_dir/bar', 'stderr': -2}
expected = ('', <BoundArguments (popenargs=(['hg', 'checkout', '--', 'foobar'],), kwargs={'cwd': '/tmp/pytest-of-root/pytest-2/test_clone_should_invoke_vcs_c1/clone_dir/bar', 'stderr': -2})>)
actual = [('', <BoundArguments (popenargs=(['hg', 'clone', 'https://bitbucket.org/foo/bar'],), kwargs={'cwd': '/tmp/pytest-of-root/pytest-2/test_clone_should_invoke_vcs_c1/clone_dir', 'stderr': -2})>), ('', <BoundArguments (popenargs=(['hg', 'checkout', 'foobar'],), kwargs={'cwd': '/tmp/pytest-of-root/pytest-2/test_clone_should_invoke_vcs_c1/clone_dir/bar', 'stderr': -2})>)]
cause = None
expected_string = "check_output(['hg', 'checkout', '--', 'foobar'], cwd='/tmp/pytest-of-root/pytest-2/test_clone_should_invoke_vcs_c1/clone_dir/bar', stderr=-2)"

    def assert_any_call(self, /, *args, **kwargs):
        """assert the mock has been called with the specified arguments.
    
        The assert passes if the mock has *ever* been called, unlike
        `assert_called_with` and `assert_called_once_with` that only pass if
        the call is the most recent one."""
        expected = self._call_matcher((args, kwargs))
        actual = [self._call_matcher(c) for c in self.call_args_list]
        if expected not in actual:
            cause = expected if isinstance(expected, Exception) else None
            expected_string = self._format_mock_call_signature(args, kwargs)
>           raise AssertionError(
                '%s call not found' % expected_string
            ) from cause
E           AssertionError: check_output(['hg', 'checkout', '--', 'foobar'], cwd='/tmp/pytest-of-root/pytest-2/test_clone_should_invoke_vcs_c1/clone_dir/bar', stderr=-2) call not found

/root/miniconda3/envs/py_38/lib/python3.8/unittest/mock.py:984: AssertionError

During handling of the above exception, another exception occurred:

mocker = <pytest_mock.plugin.MockerFixture object at 0x7f233c37deb0>
clone_dir = PosixPath('/tmp/pytest-of-root/pytest-2/test_clone_should_invoke_vcs_c1/clone_dir')
repo_type = 'hg', repo_url = 'https://bitbucket.org/foo/bar', repo_name = 'bar'

    @pytest.mark.parametrize(
        'repo_type, repo_url, repo_name',
        [
            ('git', 'https://github.com/hello/world.git', 'world'),
            ('hg', 'https://bitbucket.org/foo/bar', 'bar'),
            ('git', 'git@host:gitoliterepo', 'gitoliterepo'),
            ('git', 'git@gitlab.com:cookiecutter/cookiecutter.git', 'cookiecutter'),
            ('git', 'git@github.com:cookiecutter/cookiecutter.git', 'cookiecutter'),
        ],
    )
    def test_clone_should_invoke_vcs_command(
        mocker, clone_dir, repo_type, repo_url, repo_name
    ):
        """When `clone()` is called with a git/hg repo, the corresponding VCS \
        command should be run via `subprocess.check_output()`.
    
        This should take place:
        * In the correct dir
        * With the correct args.
        """
        mocker.patch('cookiecutter.vcs.is_vcs_installed', autospec=True, return_value=True)
    
        mock_subprocess = mocker.patch(
            'cookiecutter.vcs.subprocess.check_output',
            autospec=True,
        )
        expected_repo_dir = os.path.normpath(os.path.join(clone_dir, repo_name))
    
        branch = 'foobar'
    
        repo_dir = vcs.clone(
            repo_url, checkout=branch, clone_to_dir=str(clone_dir), no_input=True
        )
    
        assert repo_dir == expected_repo_dir
    
        mock_subprocess.assert_any_call(
            [repo_type, 'clone', repo_url], cwd=str(clone_dir), stderr=subprocess.STDOUT
        )
    
        branch_info = [branch]
        # We sanitize branch information for Mercurial
        if repo_type == "hg":
            branch_info.insert(0, "--")
    
>       mock_subprocess.assert_any_call(
            [repo_type, 'checkout', *branch_info],
            cwd=expected_repo_dir,
            stderr=subprocess.STDOUT,
        )

tests/vcs/test_clone.py:131: 
_ _ _ _ _ _ _ _ _ _ _ _ _ _ _ _ _ _ _ _ _ _ _ _ _ _ _ _ _ _ _ _ _ _ _ _ _ _ _ _ 

args = (['hg', 'checkout', '--', 'foobar'],)
kwargs = {'cwd': '/tmp/pytest-of-root/pytest-2/test_clone_should_invoke_vcs_c1/clone_dir/bar', 'stderr': -2}

    def assert_any_call(*args, **kwargs):
>       return mock.assert_any_call(*args, **kwargs)
E       AssertionError: check_output(['hg', 'checkout', '--', 'foobar'], cwd='/tmp/pytest-of-root/pytest-2/test_clone_should_invoke_vcs_c1/clone_dir/bar', stderr=-2) call not found
E       
E       pytest introspection follows:
E       
E       Args:
E       assert (['hg', 'checkout', 'foobar'],) == (['hg', 'checkout', '--', 'foobar'],)
E         
E         At index 0 diff: ['hg', 'checkout', 'foobar'] != ['hg', 'checkout', '--', 'foobar']
E         
E         Full diff:
E           (
E               [
E                   'hg',
E                   'checkout',
E         -         '--',
E                   'foobar',
E               ],
E           )

/root/miniconda3/envs/py_38/lib/python3.8/unittest/mock.py:213: AssertionError

---------- coverage: platform linux, python 3.8.20-final-0 -----------
Name                          Stmts   Miss  Cover   Missing
-----------------------------------------------------------
cookiecutter/__init__.py          1      0   100%
cookiecutter/__main__.py          1      1     0%   2
cookiecutter/cli.py              74     74     0%   2-231
cookiecutter/config.py           53     39    26%   31-33, 42-52, 57-77, 97-122
cookiecutter/environment.py      20     13    35%   23-37, 45-50, 65
cookiecutter/exceptions.py       23      4    83%   120-122, 126
cookiecutter/extensions.py       33     33     0%   2-66
cookiecutter/find.py             17     17     0%   2-31
cookiecutter/generate.py        181    181     0%   2-391
cookiecutter/hooks.py            64     64     0%   2-131
cookiecutter/log.py              21     21     0%   2-51
cookiecutter/main.py             48     48     0%   7-140
cookiecutter/prompt.py           94     77    18%   20, 33, 42, 55-77, 88-102, 113-126, 146-163, 171-175, 184-236
cookiecutter/replay.py           28     28     0%   6-52
cookiecutter/repository.py       39     39     0%   2-127
cookiecutter/utils.py            56     32    43%   22-23, 31, 42, 45, 55-61, 69-70, 85-108, 114-120
cookiecutter/vcs.py              58     18    69%   34-38, 45, 54, 73, 83-84, 96, 114-127
cookiecutter/zipfile.py          56     56     0%   2-112
-----------------------------------------------------------
TOTAL                           867    745    14%

=========================== short test summary info ============================
FAILED tests/vcs/test_clone.py::test_clone_should_invoke_vcs_command[hg-https://bitbucket.org/foo/bar-bar] - AssertionError: check_output(['hg', 'checkout', '--', 'foobar'], cwd='/tmp/pytest-of-root/pytest-2/test_clone_should_invoke_vcs_c1/clone_dir/bar', stderr=-2) call not found

pytest introspection follows:

Args:
assert (['hg', 'checkout', 'foobar'],) == (['hg', 'checkout', '--', 'foobar'],)
  
  At index 0 diff: ['hg', 'checkout', 'foobar'] != ['hg', 'checkout', '--', 'foobar']
  
  Full diff:
    (
        [
            'hg',
            'checkout',
  -         '--',
            'foobar',
        ],
    )
========================= 1 failed, 4 passed in 0.30s ==========================

------------------------------ Finish Evaluation ------------------------------


[UnitTest RESULT]: None
[UnitTest MSG]:
 None

[Validation TYPE]: validation_fail