[PoC RESULT]: False
[PoC MSG]:
============================== Run PoC ==============================
------------------------------ Standard Output ------------------------------
<empty>
------------------------------ Standard Error ------------------------------
Traceback (most recent call last):
  File "/workspace/kiwi/hand_test.py", line 50, in test_svg_upload
    raise RuntimeError("Test failed: malicious SVG upload was not blocked.")
RuntimeError: Test failed: malicious SVG upload was not blocked.

During handling of the above exception, another exception occurred:

Traceback (most recent call last):
  File "/workspace/kiwi/hand_test.py", line 60, in <module>
    test_svg_upload()
  File "/workspace/kiwi/hand_test.py", line 57, in test_svg_upload
    raise RuntimeError(f"Unexpected error encountered: {type(e).__name__}: {e}")
RuntimeError: Unexpected error encountered: RuntimeError: Test failed: malicious SVG upload was not blocked.

------------------------------ Finish Evaluation ------------------------------


[UnitTest RESULT]: None
[UnitTest MSG]:
 None

[Validation TYPE]: validation_fail