[PoC RESULT]: False
[PoC MSG]:
============================== Run PoC ==============================
------------------------------ Standard Output ------------------------------
============================= test session starts ==============================
platform linux -- Python 3.8.20, pytest-8.3.5, pluggy-1.5.0
rootdir: /workspace/notebook
plugins: nbval-0.11.0
collected 2 items

notebook/auth/tests/test_login.py .F                                     [100%]

=================================== FAILURES ===================================
____________________________ LoginTest.test_next_ok ____________________________

self = <notebook.auth.tests.test_login.LoginTest testMethod=test_next_ok>

    def test_next_ok(self):
        for next_path in (
            "tree/",
            self.base_url() + "has/host",
            "notebooks/notebook.ipynb",
            "tree//something",
        ):
            if "://" in next_path:
                expected = next_path
            else:
                expected = self.url_prefix + next_path
    
            actual = self.login(next=expected)
>           self.assertEqual(actual, expected)
E           AssertionError: '/a%40b/' != 'http://localhost:12341/a%40b/has/host'
E           - /a%40b/
E           + http://localhost:12341/a%40b/has/host

notebook/auth/tests/test_login.py:54: AssertionError
------------------------------ Captured log call -------------------------------
DEBUG    NotebookApp:handlers.py:259 Using contents: services/contents
DEBUG    NotebookApp:log.py:48 200 GET /a%40b/login (::1) 1.07ms
INFO     NotebookApp:log.py:48 302 POST /a%40b/login?next=%2Fa%2540b%2Ftree%2F (::1) 0.67ms
DEBUG    NotebookApp:handlers.py:259 Using contents: services/contents
DEBUG    NotebookApp:log.py:48 200 GET /a%40b/login (::1) 0.99ms
WARNING  NotebookApp:login.py:67 Not allowing login redirect to 'http://localhost:12341/a%40b/has/host'
INFO     NotebookApp:log.py:48 302 POST /a%40b/login?next=http%3A%2F%2Flocalhost%3A12341%2Fa%2540b%2Fhas%2Fhost (::1) 0.79ms
---------------------------- Captured log teardown -----------------------------
INFO     NotebookApp:notebookapp.py:1645 Shutting down 0 kernels
=========================== short test summary info ============================
FAILED notebook/auth/tests/test_login.py::LoginTest::test_next_ok - Assertion...
=================== 1 failed, 1 passed, 3 warnings in 0.72s ====================

------------------------------ Finish Evaluation ------------------------------


[UnitTest RESULT]: None
[UnitTest MSG]:
 None

[Validation TYPE]: validation_fail