[PoC RESULT]: False
[PoC MSG]:
============================== Run PoC ==============================
------------------------------ Standard Output ------------------------------
Testing against Django installed in '/workspace/django/django' with up to 64 processes
System check identified no issues (0 silenced).

------------------------------ Standard Error ------------------------------
F
======================================================================
FAIL: test_file_save_abs_path (file_storage.tests.FileStorageTests)
----------------------------------------------------------------------
Traceback (most recent call last):
  File "/root/miniconda3/envs/py_38/lib/python3.8/unittest/case.py", line 60, in testPartExecutor
    yield
  File "/root/miniconda3/envs/py_38/lib/python3.8/unittest/case.py", line 676, in run
    self._callTestMethod(testMethod)
  File "/root/miniconda3/envs/py_38/lib/python3.8/unittest/case.py", line 633, in _callTestMethod
    method()
  File "/workspace/django/tests/file_storage/tests.py", line 298, in test_file_save_abs_path
    self.assertEqual(f_name, test_name)
  File "/root/miniconda3/envs/py_38/lib/python3.8/unittest/case.py", line 912, in assertEqual
    assertion_func(first, second, msg=msg)
  File "/root/miniconda3/envs/py_38/lib/python3.8/unittest/case.py", line 1292, in assertMultiLineEqual
    self.fail(self._formatMessage(msg, standardMsg))
  File "/root/miniconda3/envs/py_38/lib/python3.8/unittest/case.py", line 753, in fail
    raise self.failureException(msg)
AssertionError: '/tmp/django_i1068whk/tmp6c_81h9z/path/to/test.file' != 'path/to/test.file'
- /tmp/django_i1068whk/tmp6c_81h9z/path/to/test.file
+ path/to/test.file


======================================================================
FAIL: test_storage_dangerous_paths_dir_name (file_storage.test_generate_filename.GenerateFilenameStorageTests) [<object object at 0x7fc126f3da10>] (file_name='tmp\\..\\path')
----------------------------------------------------------------------
Traceback (most recent call last):
  File "/root/miniconda3/envs/py_38/lib/python3.8/unittest/case.py", line 60, in testPartExecutor
    yield
  File "/root/miniconda3/envs/py_38/lib/python3.8/unittest/case.py", line 582, in subTest
    yield
  File "/workspace/django/tests/file_storage/test_generate_filename.py", line 67, in test_storage_dangerous_paths_dir_name
    s.get_available_name(file_name)
  File "/root/miniconda3/envs/py_38/lib/python3.8/contextlib.py", line 120, in __exit__
    next(self.gen)
  File "/workspace/django/django/test/testcases.py", line 675, in _assert_raises_or_warns_cm
    yield cm
  File "/root/miniconda3/envs/py_38/lib/python3.8/unittest/case.py", line 227, in __exit__
    self._raiseFailure("{} not raised".format(exc_name))
  File "/root/miniconda3/envs/py_38/lib/python3.8/unittest/case.py", line 164, in _raiseFailure
    raise self.test_case.failureException(msg)
AssertionError: SuspiciousFileOperation not raised

======================================================================
FAIL: test_storage_dangerous_paths_dir_name (file_storage.test_generate_filename.GenerateFilenameStorageTests) [<object object at 0x7fc126f3da10>] (file_name='\\tmp\\..\\path')
----------------------------------------------------------------------
Traceback (most recent call last):
  File "/root/miniconda3/envs/py_38/lib/python3.8/unittest/case.py", line 60, in testPartExecutor
    yield
  File "/root/miniconda3/envs/py_38/lib/python3.8/unittest/case.py", line 582, in subTest
    yield
  File "/workspace/django/tests/file_storage/test_generate_filename.py", line 67, in test_storage_dangerous_paths_dir_name
    s.get_available_name(file_name)
  File "/root/miniconda3/envs/py_38/lib/python3.8/contextlib.py", line 120, in __exit__
    next(self.gen)
  File "/workspace/django/django/test/testcases.py", line 675, in _assert_raises_or_warns_cm
    yield cm
  File "/root/miniconda3/envs/py_38/lib/python3.8/unittest/case.py", line 227, in __exit__
    self._raiseFailure("{} not raised".format(exc_name))
  File "/root/miniconda3/envs/py_38/lib/python3.8/unittest/case.py", line 164, in _raiseFailure
    raise self.test_case.failureException(msg)
AssertionError: SuspiciousFileOperation not raised

----------------------------------------------------------------------
Ran 2 tests in 0.108s

FAILED (failures=3)

------------------------------ Finish Evaluation ------------------------------


[UnitTest RESULT]: None
[UnitTest MSG]:
 None

[Validation TYPE]: validation_fail